Workbook
Name Codes: #REF!
Name Disciplines: #REF!

Sheet STR
A1: Inspection Request - STR | K1: A | L1: Approved | N1: Date: | O1: =TODAY() -> 46114
K2: B | L2: Approved with notes
K3: C | L3: Reject & Resubmit
K4: CC | L4: Not Resubmitted
K5: UR | L5: Under Review
A6: DOCUMENT REFERENCE NO | D6: Element | E6: Location | F6: DESCRIPTION | G6: Attachment | I6: Outgoing to Consultant | K6: Code Action | L6: Status | M6: Progress | N6: Over Duration | O6: scan | P6: Duration
A7: No. | B7: Referance | C7: REV | G7: Dwg | H7: Report | I7: Submission date | J7: Received Date
A9: 1 | B9: WIR-Civil-001 | C9: 0 | D9: STR | E9: Zone 2 Building : GA-(01-02-03-04-05-06-13-14-15-17-18) | F9: Compaction to 4 layers | I9: 45969 | J9: 45970 | K9: B | L9: CLOSED | M9: 1 | N9: 0 | O9: IN
A10: 2 | B10: WIR-Civil-002 | C10: 0 | D10: STR | E10: Zone 2 Building : GA-( 01-02-03-04-05-06 ) | F10: Prevention Termites , Polythene Sheet | I10: 46003 | J10: 46004 | K10: B | L10: CLOSED | M10: 1 | N10: 0 | O10: IN
A11: 3 | B11: WIR-Civil-003 | C11: 0 | D11: STR | E11: Zone 2 Building : GA-( 01-02-03-04-05-06 ) | F11: Form Work of P.C Footing | I11: 46003 | J11: 46003 | K11: B | L11: CLOSED | M11: 1 | N11: 0 | O11: IN
A12: 4 | B12: WIR-Civil-004 | C12: 0 | D12: STR | E12: Zone 2 Building : GA-( 01-02-03-04-05-06 ) | F12: Form and Steel Work of R.C Footing | I12: 46003 | J12: 46003 | K12: B | L12: CLOSED | M12: 1 | N12: 0 | O12: IN
A13: 5 | B13: WIR-Civil-005 | C13: 0 | D13: STR | E13: Zone 2 Building : GA-( 01-02-03-04-05-06 ) | F13: Surface Preparation for R.C Footing Before Insulation | I13: 46003 | J13: 46003 | K13: B | L13: CLOSED | M13: 1 | N13: 0 | O13: IN
A14: 6 | B14: WIR-Civil-006 | C14: 0 | D14: STR | E14: Zone 2 Building : GA-( 01-02-03-04-05-06 ) | F14: 1st Layer Insulation of R.C Footing | I14: 46003 | J14: 46006 | K14: B | L14: CLOSED | M14: 1 | N14: 0 | O14: IN
A15: 7 | B15: WIR-Civil-007 | C15: 0 | D15: STR | E15: Zone 2 Building : GA-( 01-02-03-04-05-06 ) | F15: 2nd Layer Insulation of R.C Footing | I15: 46003 | J15: 46006 | K15: B | L15: CLOSED | M15: 1 | N15: 0 | O15: IN
A16: 8 | B16: WIR-Civil-008 | C16: 0 | D16: STR | E16: Zone 2 Building : GA-( 01-02-03-04-05-06 ) | F16: Form and Steel Work of Grade Beam | I16: 46003 | J16: 45981 | K16: B | L16: CLOSED | M16: 1 | N16: 0 | O16: IN
A17: 9 | B17: WIR-Civil-009 | C17: 0 | D17: STR | E17: Zone 2 Building : GA-( 01-02-03-04-05-06 ) | F17: Surface Preparation for Grade Beam Before Insulation | I17: 46003 | J17: 45976 | K17: B | L17: CLOSED | M17: 1 | N17: 0 | O17: IN
A18: 10 | B18: WIR-Civil-010 | C18: 0 | D18: STR | E18: Zone 2 Building : GA-( 01-02-03-04-05-06 ) | F18: 1st Layer Insulation of Grade Beam | I18: 46003 | J18: 45976 | K18: B | L18: CLOSED | M18: 1 | N18: 0 | O18: IN
A19: 11 | B19: WIR-Civil-011 | C19: 0 | D19: STR | E19: Zone 2 Building : GA-( 01-02-03-04-05-06 ) | F19: 2nd Layer Insulation of Grade Beam | I19: 46003 | J19: 45976 | K19: B | L19: CLOSED | M19: 1 | N19: 0 | O19: IN
A20: 12 | B20: WIR-Civil-012 | C20: 0 | D20: STR | E20: Zone 2 Building : GA-( 01-02-03-04-05-06 ) | F20: Steel Work of Columns | I20: 46003 | J20: 46088 | K20: B | L20: CLOSED | M20: 1 | N20: 0 | O20: IN
... A28: 20 | B28: WIR-Civil-020 | C28: 0 | D28: STR | E28: Zone : 3 Building : twins Q-VS ( 01-02-03-04-09-10-11-12-13-19-20-21-22-33-34-35-36 ) | F28: Compaction | I28: 45984 | J28: 45984 | K28: B | L28: CLOSED | M28: 1 | N28: 0 | O28: IN
A29: 21 | B29: WIR-Civil-021 | C29: 0 | D29: STR | F29: الرد على NCR 001 | I29: 45990 | J29: 45994 | K29: S | L29: CLOSED | M29: 1 | N29: 0 | O29: IN
A30: 22 | B30: WIR-Civil-021 | C30: 1 | D30: STR | F30: الرد على NCR 001 | I30: 46001 | J30: 46072 | K30: B | L30: CLOSED | M30: 1 | N30: 0 | O30: IN
A31: 23 | B31: WIR-Civil-022 | C31: 0 | D31: STR | F31: الرد على NCR 002 | I31: 45990 | J31: 45994 | K31: S | L31: CLOSED | M31: 1 | N31: 0 | O31: IN
A32: 24 | B32: WIR-Civil-022 | C32: 1 | D32: STR | F32: الرد على NCR 002 | I32: 46001 | K32: S | L32: CLOSED | M32: 1 | N32: 0 | O32: IN
A33: 25 | B33: WIR-Civil-022 | C33: 2 | D33: STR | F33: closing NCR 002 | I33: 46001 | J33: 46072 | K33: B | L33: CLOSED | M33: 1 | N33: 0 | O33: IN
A34: 26 | B34: WIR-Civil-023 | C34: 0 | D34: STR | E34: مكرر وسيتم الغاءه | F34: NCR 005 | I34: 45990 | J34: 45994 | K34: S | L34: CLOSED | M34: 1 | N34: 0 | O34: IN
A35: 27 | B35: WIR-Civil-023 | C35: 1 | D35: STR | E35: مكرر وسيتم الغاءه | F35: الرد على NCR 005 | I35: 46001 | J35: 45994 | K35: C | L35: CLOSED | M35: 1 | N35: 0 | O35: IN
A36: 28 | B36: WIR-Civil-024 | C36: 0 | D36: STR | F36: الرد على NCR 04 | I36: 45990 | J36: 45994 | K36: S | L36: CLOSED | M36: 1 | N36: 0 | O36: IN
A37: 29 | B37: WIR-Civil-024 | C37: 1 | D37: STR | F37: الرد على NCR 04 | I37: 46001 | J37: 45994 | K37: S | L37: CLOSED | M37: 1 | N37: 0 | O37: IN
A38: 30 | B38: WIR-Civil-024 | C38: 2 | D38: STR | F38: الرد على NCR 04 | I38: 46106 | J38: 46106 | K38: B | L38: CLOSED | M38: 1 | N38: 0 | O38: IN
A39: 30 | B39: WIR-Civil-025 | C39: 0 | D39: STR | E39: Zone : 4 Building : Q-VF01 | F39: plan concrete Footing | I39: 45990 | J39: 45994 | K39: B | L39: CLOSED | M39: 1 | N39: 0 | O39: IN
A40: 31 | B40: WIR-Civil-026 | C40: 0 | D40: STR | E40: Zone : 4 Building : Q-VF01 | F40: Steel Work of R.C raft | I40: 45991 | J40: 45991 | K40: C | L40: CLOSED | M40: 1 | N40: 0 | O40: IN
A41: 32 | B41: WIR-Civil-027 | C41: 0 | D41: STR | E41: Zone : 4 Building : Q-VF01 | F41: Surface Preparation for R.C Footing Before Insulation | I41: 45991 | J41: 45991 | K41: B | L41: CLOSED | M41: 1 | N41: 0 | O41: IN
A42: 33 | B42: WIR-Civil-028 | C42: 0 | D42: STR | E42: Zone : 4 Building : Q-VF01 | F42: 1st Layer Insulation of R.C raft | I42: 45991 | J42: 45991 | K42: B | L42: CLOSED | M42: 1 | N42: 0 | O42: IN
A43: 34 | B43: WIR-Civil-029 | C43: 0 | D43: STR | E43: Zone : 4 Building : Q-VF01 | F43: 2nd Layer Insulation of R.C raft | I43: 45991 | J43: 45991 | K43: B | L43: CLOSED | M43: 1 | N43: 0 | O43: IN
A44: 35 | B44: WIR-Civil-030 | C44: 0 | D44: STR | E44: Zone : 4 Building : Q-VF01 | F44: Form and Steel Work of Grade Beam | I44: 45991 | J44: 45991 | K44: C | L44: CLOSED | M44: 1 | N44: 0 | O44: IN
B45: WIR-Civil-030 | C45: 1 | D45: STR | E45: Zone : 4 Building : Q-VF01 | F45: Form and Steel Work of Grade Beam | I45: 46004 | J45: 46006 | K45: D
A46: 36 | B46: WIR-Civil-031 | C46: 0 | D46: STR | E46: Zone : 4 Building : Q-VS01 | F46: Form Work of P.C raft | I46: 45991 | J46: 45991 | K46: B | L46: CLOSED | M46: 1 | N46: 0 | O46: IN
A47: 37 | B47: WIR-Civil-032 | C47: 0 | D47: STR | E47: Zone : 4 Building : Q-VS01 | F47: Form and Steel Work of R.C raft | I47: 45991 | J47: 45991 | K47: B | L47: CLOSED | M47: 1 | N47: 0 | O47: IN
A48: 38 | B48: WIR-Civil-033 | C48: 0 | D48: STR | E48: Zone : 4 Building : Q-VS01 | F48: Surface Preparation for R.C raft Before Insulation | I48: 45991 | J48: 45991 | K48: B | L48: CLOSED | M48: 1 | N48: 0 | O48: IN
...

Sheet ARCH
A1: Inspection Request - ARCH | K1: A | L1: Approved | N1: Date: | O1: =TODAY() -> 46114
K2: B | L2: Approved with notes
K3: C | L3: Reject & Resubmit
K4: CC | L4: Not Resubmitted
K5: UR | L5: Under Review
A6: DOCUMENT REFERENCE NO | D6: Element | E6: Location | F6: DESCRIPTION | G6: Attachment | I6: Outgoing to Consultant | K6: Code Action | L6: Status | M6: Progress | N6: Over Duration | O6: scan | P6: Duration
A7: No. | B7: Reference | C7: REV | G7: Dwg | H7: Report | I7: Submission date | J7: Received Date
A9: 1 | B9: WIR-ARCH-001 | C9: 0 | F9: NCR Clossing 001 | I9: 46014 | J9: 46018 | K9: S | O9: =HYPERLINK(CONCATENATE("Project Name\01- Inspection Request - IR\STR\",B9,"-",C9,".PDF"),"IN") -> IN | P9: =IF(C13=0,I13+1,IF(C13>0,I13+1)) -> 46359
B10: WIR-ARCH-001 | C10: 1 | F10: NCR Clossing 001 | I10: 46057 | J10: 46057 | K10: B
A11: 2 | B11: WIR-ARCH-002 | C11: 0 | F11: NCR Clossing 002 | I11: 46379 | J11: 46023 | K11: C | O11: =HYPERLINK(CONCATENATE("Project Name\01- Inspection Request - IR\STR\",B11,"-",C11,".PDF"),"IN") -> IN | P11: =IF(C14=0,I14+1,IF(C14>0,I14+1)) -> 46359
A12: 3 | B12: WIR-ARCH-002 | C12: 1 | F12: NCR Clossing 002 | K12: UR
A13: 4 | B13: WIR-ARCH-003 | C13: 0 | E13: Q-R01 | F13: Inspection of the first fix plastring works | I13: 46358 | J13: 46068 | K13: D | O13: =HYPERLINK(CONCATENATE("Project Name\01- Inspection Request - IR\STR\",B13,"-",C13,".PDF"),"IN") -> IN | P13: =IF(C15=0,I15+1,IF(C15>0,I15+1)) -> 46359
A14: 5 | B14: WIR-ARCH-004 | C14: 0 | E14: Q-R01 | F14: Inspection of the Second fix plastring works | I14: 46358 | J14: 46068 | K14: D | O14: =HYPERLINK(CONCATENATE("Project Name\01- Inspection Request - IR\STR\",B14,"-",C14,".PDF"),"IN") -> IN | P14: =IF(C16=0,I16+1,IF(C16>0,I16+1)) -> 46359
A15: 6 | B15: WIR-ARCH-005 | C15: 0 | E15: Q-R01 | F15: Inspection of wall sealer paint works | I15: 46358 | J15: 46068 | K15: C | O15: =HYPERLINK(CONCATENATE("Project Name\01- Inspection Request - IR\STR\",B15,"-",C15,".PDF"),"IN") -> IN | P15: =IF(C17=0,I17+1,IF(C17>0,I17+1)) -> 46359
A16: 7 | B16: WIR-ARCH-006 | C16: 0 | E16: Q-R01 | F16: Inspection of the first coat putty works | I16: 46358 | J16: 46068 | K16: C | O16: =HYPERLINK(CONCATENATE("Project Name\01- Inspection Request - IR\STR\",B16,"-",C16,".PDF"),"IN") -> IN
A17: 8 | B17: WIR-ARCH-007 | C17: 0 | E17: Q-R01 | F17: Inspection of the Second coat putty works | I17: 46358 | J17: 46068 | K17: C | O17: =HYPERLINK(CONCATENATE("Project Name\01- Inspection Request - IR\STR\",B17,"-",C17,".PDF"),"IN") -> IN
A18: 9 | B18: WIR-ARCH-008 | C18: 0 | E18: Q-R01 | F18: Inspection of the Third coat putty works | I18: 46065 | J18: 46068 | K18: C | O18: =HYPERLINK(CONCATENATE("Project Name\01- Inspection Request - IR\STR\",B18,"-",C18,".PDF"),"IN") -> IN
A19: 10 | B19: WIR-ARCH-009 | C19: 0 | E19: Q-R01 | F19: Inspection of the first coat wall painting works | I19: 46065 | J19: 46068 | K19: C | O19: =HYPERLINK(CONCATENATE("Project Name\01- Inspection Request - IR\STR\",B19,"-",C19,".PDF"),"IN") -> IN
A20: 11 | B20: WIR-ARCH-010 | C20: 0 | E20: Q-R01 | F20: Inspection of the second coat wall painting works | I20: 46065 | J20: 46068 | K20: C | O20: =HYPERLINK(CONCATENATE("Project Name\01- Inspection Request - IR\STR\",B20,"-",C20,".PDF"),"IN") -> IN
A21: 12 | B21: WIR-ARCH-011 | C21: 0 | E21: Q-R01 | F21: Inspection of the first fix of gybsm board | I21: 46065 | J21: 46068 | K21: B | O21: =HYPERLINK(CONCATENATE("Project Name\01- Inspection Request - IR\STR\",B21,"-",C21,".PDF"),"IN") -> IN
A22: 13 | B22: WIR-ARCH-012 | C22: 0 | E22: Q-R01 | F22: Inspection of the second fix of gybsm board | I22: 46065 | J22: 46068 | K22: B | O22: =HYPERLINK(CONCATENATE("Project Name\01- Inspection Request - IR\STR\",B22,"-",C22,".PDF"),"IN") -> IN
A23: 14 | B23: WIR-ARCH-013 | C23: 0 | E23: Q-R03 | F23: Inspection of the first fix plastring works | I23: 46065 | J23: 46068 | K23: D | O23: =HYPERLINK(CONCATENATE("Project Name\01- Inspection Request - IR\STR\",B23,"-",C23,".PDF"),"IN") -> IN
A24: 15 | B24: WIR-ARCH-014 | C24: 0 | E24: Q-R03 | F24: Inspection of the second fix plastring works | I24: 46065 | J24: 46068 | K24: D | O24: =HYPERLINK(CONCATENATE("Project Name\01- Inspection Request - IR\STR\",B24,"-",C24,".PDF"),"IN") -> IN
A25: 16 | B25: WIR-ARCH-015 | C25: 0 | E25: Q-R03 | F25: Inspection of wall sealer paint works | I25: 46065 | J25: 46068 | K25: C | O25: =HYPERLINK(CONCATENATE("Project Name\01- Inspection Request - IR\STR\",B25,"-",C25,".PDF"),"IN") -> IN
A26: 17 | B26: WIR-ARCH-016 | C26: 0 | E26: Q-R03 | F26: Inspection of the first coat wall putty works | I26: 46065 | J26: 46068 | K26: C | O26: =HYPERLINK(CONCATENATE("Project Name\01- Inspection Request - IR\STR\",B26,"-",C26,".PDF"),"IN") -> IN
A27: 18 | B27: WIR-ARCH-017 | C27: 0 | E27: Q-R03 | F27: Inspection of the Second coat wall putty works | I27: 46065 | J27: 46068 | K27: C | O27: =HYPERLINK(CONCATENATE("Project Name\01- Inspection Request - IR\STR\",B27,"-",C27,".PDF"),"IN") -> IN
... A40: 31 | B40: WIR-ARCH-030 | C40: 0 | E40: Q-R05 | F40: Inspection of the second coat wall painting works | I40: 46065 | J40: 46068 | K40: C | O40: =HYPERLINK(CONCATENATE("Project Name\01- Inspection Request - IR\STR\",B40,"-",C40,".PDF"),"IN") -> IN
A41: 32 | B41: WIR-ARCH-031 | C41: 0 | F41: Closing NCR 016 | I41: 46035 | J41: 46038 | K41: B | O41: =HYPERLINK(CONCATENATE("Project Name\01- Inspection Request - IR\STR\",B41,"-",C41,".PDF"),"IN") -> IN
A42: 33 | B42: WIR-ARCH-032 | C42: 0 | F42: Closing NCR 017 | I42: 46035 | J42: 46038 | K42: B | O42: =HYPERLINK(CONCATENATE("Project Name\01- Inspection Request - IR\STR\",B42,"-",C42,".PDF"),"IN") -> IN
A43: 34 | B43: WIR-ARCH-033 | C43: 0 | F43: Closing NCR 015 | I43: 46035 | J43: 46040 | K43: C | O43: =HYPERLINK(CONCATENATE("Project Name\01- Inspection Request - IR\STR\",B43,"-",C43,".PDF"),"IN") -> IN
A44: 35 | B44: WIR-ARCH-033 | C44: 1 | F44: Closing NCR 015 | K44: UR | O44: =HYPERLINK(CONCATENATE("Project Name\01- Inspection Request - IR\STR\",B44,"-",C44,".PDF"),"IN") -> IN
A45: 36 | B45: WIR-ARCH-034 | C45: 0 | F45: Closed Non Conformance Report No.( NCR-ARCH-021) | K45: UR | O45: =HYPERLINK(CONCATENATE("Project Name\01- Inspection Request - IR\STR\",B45,"-",C45,".PDF"),"IN") -> IN
A46: 37 | B46: WIR-ARCH-035 | C46: 0 | F46: Closed Non Conformance Report No.( NCR-ARCH-020) | K46: UR | O46: =HYPERLINK(CONCATENATE("Project Name\01- Inspection Request - IR\STR\",B46,"-",C46,".PDF"),"IN") -> IN
A47: 38 | B47: WIR-ARCH-036 | C47: 0 | F47: Closed Non Conformance Report No.( NCR-ARCH-03) | K47: UR | O47: =HYPERLINK(CONCATENATE("Project Name\01- Inspection Request - IR\STR\",B47,"-",C47,".PDF"),"IN") -> IN
A48: 39 | B48: WIR-ARCH-037 | C48: 0 | F48: Closed Non Conformance Report No.( NCR-ARCH-04) | K48: B | O48: =HYPERLINK(CONCATENATE("Project Name\01- Inspection Request - IR\STR\",B48,"-",C48,".PDF"),"IN") -> IN
A49: 40 | B49: WIR-ARCH-038 | C49: 0 | F49: Closed Non Conformance Report No.( NCR-ARCH-05) | K49: B | O49: =HYPERLINK(CONCATENATE("Project Name\01- Inspection Request - IR\STR\",B49,"-",C49,".PDF"),"IN") -> IN
A50: 41 | B50: WIR-ARCH-039 | C50: 0 | F50: Closed Non Conformance Report No.( NCR-ARCH-06) | K50: B | O50: =HYPERLINK(CONCATENATE("Project Name\01- Inspection Request - IR\STR\",B50,"-",C50,".PDF"),"IN") -> IN
A51: 42 | B51: WIR-ARCH-040 | C51: 0 | F51: Closed Non Conformance Report No.( NCR-ARCH-019) | K51: UR | O51: =HYPERLINK(CONCATENATE("Project Name\01- Inspection Request - IR\STR\",B51,"-",C51,".PDF"),"IN") -> IN
A52: 43 | B52: WIR-ARCH-041 | C52: 0 | F52: Closed Non Conformance Report No.( NCR-ARCH-08) | K52: UR | O52: =HYPERLINK(CONCATENATE("Project Name\01- Inspection Request - IR\STR\",B52,"-",C52,".PDF"),"IN") -> IN
A53: 44 | B53: WIR-ARCH-042 | C53: 0 | F53: Closed Non Conformance Report No.( NCR-ARCH-09) | K53: UR | O53: =HYPERLINK(CONCATENATE("Project Name\01- Inspection Request - IR\STR\",B53,"-",C53,".PDF"),"IN") -> IN
...

Sheet ELEC
A1: Inspection Request - ELEC | K1: A | L1: Approved | N1: Date: | O1: =TODAY() -> 46114
K2: B | L2: Approved with notes
K3: C | L3: Reject & Resubmit
K4: CC | L4: Not Resubmitted
K5: UR | L5: Under Review
A6: DOCUMENT REFERENCE NO | D6: Element | E6: Location | F6: DESCRIPTION | G6: Attachment | I6: Outgoing to Consultant | K6: Code Action | L6: Status | M6: Progress | N6: Over Duration | O6: scan | P6: Attachement
A7: No. | B7: Reference | C7: REV | G7: Dwg | H7: Report | I7: Submission date | J7: Received Date
A9: 1 | B9: WIR-ELEC-001 | C9: 0 | D9: Electrical | F9: Closing NCR 002 | I9: 46012 | J9: 46016 | K9: B | O9: =HYPERLINK(CONCATENATE("Project Name\01- Inspection Request - IR\STR\",B9,"-",C9,".PDF"),"IN") -> IN
A10: 2 | B10: WIR-ELEC-002 | C10: 0 | D10: Electrical | F10: Closing NCR 003 | I10: 46012 | J10: 46018 | K10: B | O10: =HYPERLINK(CONCATENATE("Project Name\01- Inspection Request - IR\STR\",B10,"-",C10,".PDF"),"IN") -> IN
A11: 3 | B11: WIR-ELEC-003 | C11: 0 | D11: Electrical | F11: Closing NCR 004 | I11: 46014 | J11: 46016 | K11: B | O11: =HYPERLINK(CONCATENATE("Project Name\01- Inspection Request - IR\STR\",B11,"-",C11,".PDF"),"IN") -> IN
A12: 4 | B12: WIR-ELEC-004 | C12: 0 | D12: Electrical | F12: Inspection of sleeves for power cable and low current cable | I12: 46035 | J12: 46037 | K12: C
A13: 5 | B13: WIR-ELEC-005 | C13: 0 | D13: Electrical | F13: Inspection of first fix for power lighting, low current(Wall celing | I13: 46035 | J13: 46037 | K13: C
A14: 6 | B14: WIR-ELEC-006 | C14: 0 | D14: Electrical | F14: Inspection of wire pulling for lighting and power | I14: 46035 | J14: 46037 | K14: C
A15: 7 | B15: WIR-ELEC-007 | C15: 0 | D15: Electrical | F15: Inspection of installation of lighting fixtures | I15: 46035 | J15: 46037 | K15: C
A16: 8 | B16: WIR-ELEC-008 | C16: 0 | D16: Electrical | F16: Inspection of installation of lighting switches & power sockets | I16: 46035 | J16: 46037 | K16: C
A17: 9 | B17: WIR-ELEC-009 | C17: 0 | D17: Electrical | F17: Inspction of fire alaram cable pulling | I17: 46035 | J17: 46037 | K17: C
A18: 10 | B18: WIR-ELEC-010 | C18: 0 | D18: Electrical | F18: Inspection of installation of fire alaram devices | I18: 46035 | J18: 46037 | K18: C
A19: 11 | B19: WIR-ELEC-011 | C19: 0 | D19: Electrical | F19: Inspection of fire alaram panel imnstallation | I19: 46035 | J19: 46035 | K19: D
A20: 12 | B20: WIR-ELEC-012 | C20: 0 | D20: Electrical | F20: Inspection of fire alaram testing | I20: 46035 | J20: 46037 | K20: C | O20: =HYPERLINK(CONCATENATE("Project Name\01- Inspection Request - IR\STR\",B20,"-",C20,".PDF"),"IN") -> IN | P20: 3-1 | Q20: 17-0
A21: 13 | B21: WIR-ELEC-013 | C21: 0 | D21: Electrical | F21: Inspection of lighting fixtures testing | I21: 46035 | J21: 46037 | K21: C | O21: =HYPERLINK(CONCATENATE("Project Name\01- Inspection Request - IR\STR\",B21,"-",C21,".PDF"),"IN") -> IN | P21: 3-1 | Q21: 17-0 | R21: 18-0
A22: 14 | B22: WIR-ELEC-014 | C22: 0 | D22: Electrical | F22: Inspection of distribution board testing | I22: 46035 | J22: 46037 | K22: C | O22: =HYPERLINK(CONCATENATE("Project Name\01- Inspection Request - IR\STR\",B22,"-",C22,".PDF"),"IN") -> IN | P22: 17-0 | Q22: 18-0
A23: 15 | B23: WIR-ELEC-015 | C23: 0 | D23: Electrical | F23: NCR CLOSING 019 | I23: 46068 | J23: 15/2/2026 | K23: C | O23: =HYPERLINK(CONCATENATE("Project Name\01- Inspection Request - IR\STR\",B23,"-",C23,".PDF"),"IN") -> IN | P23: 18-0
B24: WIR-ELEC-015 | C24: 1 | D24: Electrical | F24: NCR CLOSING 019 | K24: UR
A25: 16 | B25: WIR-ELEC-016 | C25: 0 | D25: Electrical | F25: NCR CLOSING 005 | I25: 46068 | J25: 46070 | K25: C | O25: =HYPERLINK(CONCATENATE("Project Name\01- Inspection Request - IR\STR\",B25,"-",C25,".PDF"),"IN") -> IN | P25: 17-0 | Q25: 18-0
B26: WIR-ELEC-016 | C26: 1 | D26: Electrical | F26: NCR CLOSING 005 | I26: 46068 | J26: 46072 | K26: C
A27: 17 | B27: WIR-ELEC-017 | C27: 0 | D27: Electrical | F27: NCR CLOSING 020 | I27: 46068 | J27: 15/2/2026 | K27: C | O27: =HYPERLINK(CONCATENATE("Project Name\01- Inspection Request - IR\STR\",B27,"-",C27,".PDF"),"IN") -> IN | P27: 4-1
A28: 18 | B28: WIR-ELEC-018 | C28: 0 | D28: Electrical | F28: NCR CLOSING 018 | I28: 46068 | J28: 46072 | K28: B | O28: =HYPERLINK(CONCATENATE("Project Name\01- Inspection Request - IR\STR\",B28,"-",C28,".PDF"),"IN") -> IN
A29: 19 | B29: WIR-ELEC-019 | C29: 0 | D29: Electrical | F29: NCR CLOSING 001 | I29: 46068 | J29: 15/2/2026 | K29: C | O29: =HYPERLINK(CONCATENATE("Project Name\01- Inspection Request - IR\STR\",B29,"-",C29,".PDF"),"IN") -> IN | P29: 4-1
A30: 20 | B30: WIR-ELEC-020 | C30: 0 | D30: Electrical | F30: NCR CLOSING 013 | I30: 46068 | J30: 46072 | K30: B | O30: =HYPERLINK(CONCATENATE("Project Name\01- Inspection Request - IR\STR\",B30,"-",C30,".PDF"),"IN") -> IN
A31: 21 | B31: WIR-ELEC-021 | C31: 0 | D31: Electrical | F31: NCR CLOSING 016 | I31: 46068 | J31: 46094 | K31: B | O31: =HYPERLINK(CONCATENATE("Project Name\01- Inspection Request - IR\STR\",B31,"-",C31,".PDF"),"IN") -> IN | P31: 18-0
A32: 22 | B32: WIR-ELEC-022 | C32: 0 | D32: Electrical | F32: NCR CLOSING 008 | I32: 46068 | J32: 46083 | K32: B | O32: =HYPERLINK(CONCATENATE("Project Name\01- Inspection Request - IR\STR\",B32,"-",C32,".PDF"),"IN") -> IN | P32: 17-0
A33: 23 | B33: WIR-ELEC-023 | C33: 0 | D33: Electrical | F33: NCR CLOSING 007 | I33: 46068 | J33: 46077 | K33: B | O33: =HYPERLINK(CONCATENATE("Project Name\01- Inspection Request - IR\STR\",B33,"-",C33,".PDF"),"IN") -> IN
A34: 24 | B34: WIR-ELEC-024 | C34: 0 | D34: Electrical | F34: NCR CLOSING 017 | I34: 46068 | J34: 46077 | K34: B | O34: =HYPERLINK(CONCATENATE("Project Name\01- Inspection Request - IR\STR\",B34,"-",C34,".PDF"),"IN") -> IN
A35: 25 | B35: WIR-ELEC-025 | C35: 0 | D35: Electrical | F35: NCR CLOSING 015 | I35: 46068 | J35: 46077 | K35: B | O35: =HYPERLINK(CONCATENATE("Project Name\01- Inspection Request - IR\STR\",B35,"-",C35,".PDF"),"IN") -> IN
A36: 26 | B36: WIR-ELEC-026 | C36: 0 | D36: Electrical | F36: NCR CLOSING 021 | I36: 31/3/2026 | K36: UR | O36: =HYPERLINK(CONCATENATE("Project Name\01- Inspection Request - IR\STR\",B36,"-",C36,".PDF"),"IN") -> IN | P36: 18-0
A37: 27 | B37: WIR-ELEC-027 | C37: 0 | D37: Electrical | F37: INSPACTION OF FIRST FIX OF LIGHTING,POWER SYSTEM INSTALLATION OF DB ENCLOSURE | I37: 46070 | J37: 46076 | K37: B | O37: =HYPERLINK(CONCATENATE("Project Name\01- Inspection Request - IR\STR\",B37,"-",C37,".PDF"),"IN") -> IN | P37: 17-0 | Q37: 18-0
A38: 28 | B38: WIR-ELEC-028 | C38: 0 | D38: Electrical | F38: INSTALTION OF ERTHING SYSTEM (CABLE POLLING ) ,ERTHING RODS ,PITS | I38: 46070 | K38: C | O38: =HYPERLINK(CONCATENATE("Project Name\01- Inspection Request - IR\STR\",B38,"-",C38,".PDF"),"IN") -> IN | P38: 4-1
A39: 29 | B39: WIR-ELEC-029 | C39: 0 | D39: Electrical | F39: INSPACTION OF WIRE PULLING | I39: 46070 | J39: 46076 | K39: B | O39: =HYPERLINK(CONCATENATE("Project Name\01- Inspection Request - IR\STR\",B39,"-",C39,".PDF"),"IN") -> IN | P39: 4-1
A40: 30 | B40: WIR-ELEC-030 | C40: 0 | D40: Electrical | F40: INSTALTION OF ERTHING SYSTEM (CABLE POLLING ) ,ERTHING RODS ,PITS | I40: 46070 | J40: 46076 | K40: C | O40: =HYPERLINK(CONCATENATE("Project Name\01- Inspection Request - IR\STR\",B40,"-",C40,".PDF"),"IN") -> IN | P40: 4-1
A41: 31 | B41: WIR-ELEC-031 | C41: 0 | D41: Electrical | E41: Q-VF(01-02-03-04-05) Q-VS (1 - 2-3-4-5-6-7-8-0) | F41: INSPACTION OF TERMINATION OF DB , INSTALLTION AND TERMINATION OF LIGHTING FITTINGS & WIRING ACCESSORIES | I41: 46070 | J41: 46076 | K41: B | O41: =HYPERLINK(CONCATENATE("Project Name\01- Inspection Request - IR\STR\",B41,"-",C41,".PDF"),"IN") -> IN | P41: 4-1
...

Sheet MECH
A1: Inspection Request - MECH | K1: A | L1: Approved | N1: Date: | O1: =TODAY() -> 46114
K2: B | L2: Approved with notes
K3: C | L3: Reject & Resubmit
K4: CC | L4: Not Resubmitted
K5: UR | L5: Under Review
A6: DOCUMENT REFERENCE NO | D6: Element | E6: Location | F6: DESCRIPTION | G6: Attachment | I6: Outgoing to Consultant | K6: Code Action | L6: Status | M6: Progress | N6: Over Duration | O6: scan | P6: Duration
A7: No | B7: Referance | C7: Rev | G7: Dwg | H7: Report | I7: Submission date | J7: Received Date
A8: =ROW(A1) -> 1 | B8: WIR-MECH-001 | C8: 0 | E8: Zone: 04 Building:VF-01 | F8: drainage pipes in concrete | G8: 1 | H8: 5 | I8: 45974 | J8: 45979 | K8: B | L8: =IF(K8="UR","PENDING",IF(K8="CC","OPEN","CLOSED")) -> CLOSED | M8: =IF(J8="",TODAY()-I8,J8-I8) -> 5 | N8: 0 | O8: =HYPERLINK(CONCATENATE("Project Name\01- Inspection Request - IR\STR\",B8,"-",C8,".PDF"),"IN") -> IN | P8: =IF(C8=0,I8+1,IF(C8>0,I8+1)) -> 45975
A9: =ROW(A2) -> 2 | B9: WIR-MECH-002 | C9: 0 | E9: Zone: 04 Building:VF-02 | F9: drainage pipes in concrete | G9: 1 | H9: 5 | I9: 45974 | J9: 45979 | K9: B | L9: =IF(K9="UR","PENDING",IF(K9="CC","OPEN","CLOSED")) -> CLOSED | M9: =IF(J9="",TODAY()-I9,J9-I9) -> 5 | N9: 0 | O9: =HYPERLINK(CONCATENATE("Project Name\01- Inspection Request - IR\STR\",B9,"-",C9,".PDF"),"IN") -> IN | P9: =IF(C9=0,I9+1,IF(C9>0,I9+1)) -> 45975
A10: =ROW(A3) -> 3 | B10: WIR-MECH-003 | C10: 0 | E10: Zone: 04 Building:VF-03 | F10: drainage pipes in concrete | G10: 1 | H10: 5 | I10: 45974 | J10: 45979 | K10: B | L10: =IF(K10="UR","PENDING",IF(K10="CC","OPEN","CLOSED")) -> CLOSED | M10: =IF(J10="",TODAY()-I10,J10-I10) -> 5 | N10: 0 | O10: =HYPERLINK(CONCATENATE("Project Name\01- Inspection Request - IR\STR\",B10,"-",C10,".PDF"),"IN") -> IN | P10: =IF(C10=0,I10+1,IF(C10>0,I10+1)) -> 45975
A11: =ROW(A4) -> 4 | B11: WIR-MECH-004 | C11: 0 | E11: Zone: 04 Building:VF-04 | F11: drainage pipes in concrete | G11: 1 | H11: 5 | I11: 45974 | J11: 45979 | K11: B | L11: =IF(K11="UR","PENDING",IF(K11="CC","OPEN","CLOSED")) -> CLOSED | M11: =IF(J11="",TODAY()-I11,J11-I11) -> 5 | N11: 0 | O11: =HYPERLINK(CONCATENATE("Project Name\01- Inspection Request - IR\STR\",B11,"-",C11,".PDF"),"IN") -> IN | P11: =IF(C11=0,I11+1,IF(C11>0,I11+1)) -> 45975
A12: =ROW(A5) -> 5 | B12: WIR-MECH-005 | C12: 0 | E12: Zone: 04 Building:VF-05 | F12: drainage pipes in concrete | G12: 1 | H12: 5 | I12: 45974 | J12: 45979 | K12: B | L12: =IF(K12="UR","PENDING",IF(K12="CC","OPEN","CLOSED")) -> CLOSED | M12: =IF(J12="",TODAY()-I12,J12-I12) -> 5 | N12: 0 | O12: =HYPERLINK(CONCATENATE("Project Name\01- Inspection Request - IR\STR\",B12,"-",C12,".PDF"),"IN") -> IN | P12: =IF(C12=0,I12+1,IF(C12>0,I12+1)) -> 45975
A13: =ROW(A6) -> 6 | B13: WIR-MECH-006 | C13: 0 | E13: Zone: 04 Building:VF-06 | F13: drainage pipes in concrete | G13: 1 | H13: 5 | I13: 45974 | J13: 45979 | K13: B | L13: =IF(K13="UR","PENDING",IF(K13="CC","OPEN","CLOSED")) -> CLOSED | M13: =IF(J13="",TODAY()-I13,J13-I13) -> 5 | N13: =IF(P13="",0,(IF(J13="",TODAY()-P13,IF(J13-P13>0,J13-P13,0)))) -> 0 | O13: =HYPERLINK(CONCATENATE("Project Name\01- Inspection Request - IR\STR\",B13,"-",C13,".PDF"),"IN") -> IN
A14: =ROW(A7) -> 7 | B14: WIR-MECH-007 | C14: 0 | E14: Zone: 04 Building:VF-07 | F14: drainage pipes in concrete | G14: 1 | H14: 5 | I14: 45974 | J14: 45979 | K14: B | L14: =IF(K14="UR","PENDING",IF(K14="CC","OPEN","CLOSED")) -> CLOSED | M14: =IF(J14="",TODAY()-I14,J14-I14) -> 5 | N14: =IF(P14="",0,(IF(J14="",TODAY()-P14,IF(J14-P14>0,J14-P14,0)))) -> 0 | O14: =HYPERLINK(CONCATENATE("Project Name\01- Inspection Request - IR\STR\",B14,"-",C14,".PDF"),"IN") -> IN
A15: =ROW(A8) -> 8 | B15: WIR-MECH-008 | C15: 0 | E15: Zone: 04 Building:VF-08 | F15: drainage pipes in concrete | G15: 1 | H15: 5 | I15: 45974 | J15: 45979 | K15: B | L15: =IF(K15="UR","PENDING",IF(K15="CC","OPEN","CLOSED")) -> CLOSED | M15: =IF(J15="",TODAY()-I15,J15-I15) -> 5 | N15: =IF(P15="",0,(IF(J15="",TODAY()-P15,IF(J15-P15>0,J15-P15,0)))) -> 0 | O15: =HYPERLINK(CONCATENATE("Project Name\01- Inspection Request - IR\STR\",B15,"-",C15,".PDF"),"IN") -> IN
A16: =ROW(A9) -> 9 | B16: WIR-MECH-009 | C16: 0 | E16: Zone: 04 Building:VF-09 | F16: drainage pipes in concrete | G16: 1 | H16: 5 | I16: 45978 | J16: 45979 | K16: B | L16: =IF(K16="UR","PENDING",IF(K16="CC","OPEN","CLOSED")) -> CLOSED | M16: =IF(J16="",TODAY()-I16,J16-I16) -> 1 | N16: =IF(P16="",0,(IF(J16="",TODAY()-P16,IF(J16-P16>0,J16-P16,0)))) -> 0 | O16: =HYPERLINK(CONCATENATE("Project Name\01- Inspection Request - IR\STR\",B16,"-",C16,".PDF"),"IN") -> IN
A17: =ROW(A10) -> 10 | B17: WIR-MECH-010 | C17: 0 | E17: Zone: 04 Building:VF-10 | F17: drainage pipes in concrete | G17: 1 | H17: 5 | I17: 45978 | J17: 45979 | K17: B | L17: =IF(K17="UR","PENDING",IF(K17="CC","OPEN","CLOSED")) -> CLOSED | M17: =IF(J17="",TODAY()-I17,J17-I17) -> 1 | N17: =IF(P17="",0,(IF(J17="",TODAY()-P17,IF(J17-P17>0,J17-P17,0)))) -> 0 | O17: =HYPERLINK(CONCATENATE("Project Name\01- Inspection Request - IR\STR\",B17,"-",C17,".PDF"),"IN") -> IN
A18: =ROW(A11) -> 11 | B18: WIR-MECH-011 | C18: 0 | E18: Zone: 04 Building:VS-01/VS-02 | F18: drainage pipes in concrete | G18: 1 | H18: 5 | I18: 45978 | J18: 45979 | K18: B | L18: =IF(K18="UR","PENDING",IF(K18="CC","OPEN","CLOSED")) -> CLOSED | M18: =IF(J18="",TODAY()-I18,J18-I18) -> 1 | N18: =IF(P18="",0,(IF(J18="",TODAY()-P18,IF(J18-P18>0,J18-P18,0)))) -> 0 | O18: =HYPERLINK(CONCATENATE("Project Name\01- Inspection Request - IR\STR\",B18,"-",C18,".PDF"),"IN") -> IN
A19: =ROW(A12) -> 12 | B19: WIR-MECH-012 | C19: 0 | E19: Zone: 04 Building:VS-03/VS-04 | F19: drainage pipes in concrete | G19: 1 | H19: 5 | I19: 45978 | J19: 45979 | K19: B | L19: =IF(K19="UR","PENDING",IF(K19="CC","OPEN","CLOSED")) -> CLOSED | M19: =IF(J19="",TODAY()-I19,J19-I19) -> 1 | N19: =IF(P19="",0,(IF(J19="",TODAY()-P19,IF(J19-P19>0,J19-P19,0)))) -> 0 | O19: =HYPERLINK(CONCATENATE("Project Name\01- Inspection Request - IR\STR\",B19,"-",C19,".PDF"),"IN") -> IN
A20: =ROW(A13) -> 13 | B20: WIR-MECH-013 | C20: 0 | E20: Zone: 04 Building:VS-05 | F20: drainage pipes in concrete | G20: 1 | H20: 5 | I20: 45978 | J20: 45979 | K20: B | L20: =IF(K20="UR","PENDING",IF(K20="CC","OPEN","CLOSED")) -> CLOSED | M20: =IF(J20="",TODAY()-I20,J20-I20) -> 1 | N20: =IF(P20="",0,(IF(J20="",TODAY()-P20,IF(J20-P20>0,J20-P20,0)))) -> 0 | O20: =HYPERLINK(CONCATENATE("Project Name\01- Inspection Request - IR\STR\",B20,"-",C20,".PDF"),"IN") -> IN
A21: =ROW(A14) -> 14 | B21: WIR-MECH-014 | C21: 0 | E21: Zone: 04 Building:VS-06/VS07 | F21: drainage pipes in concrete | G21: 1 | H21: 5 | I21: 45978 | J21: 45979 | K21: B | L21: =IF(K21="UR","PENDING",IF(K21="CC","OPEN","CLOSED")) -> CLOSED | M21: =IF(J21="",TODAY()-I21,J21-I21) -> 1 | N21: =IF(P21="",0,(IF(J21="",TODAY()-P21,IF(J21-P21>0,J21-P21,0)))) -> 0 | O21: =HYPERLINK(CONCATENATE("Project Name\01- Inspection Request - IR\STR\",B21,"-",C21,".PDF"),"IN") -> IN
A22: =ROW(A15) -> 15 | B22: WIR-MECH-015 | C22: 0 | E22: Zone: 04 Building:VS-08/VS-09 | F22: drainage pipes in concrete | G22: 1 | H22: 5 | I22: 45990 | J22: 46005 | K22: B | L22: =IF(K22="UR","PENDING",IF(K22="CC","OPEN","CLOSED")) -> CLOSED | M22: =IF(J22="",TODAY()-I22,J22-I22) -> 15 | N22: =IF(P22="",0,(IF(J22="",TODAY()-P22,IF(J22-P22>0,J22-P22,0)))) -> 0 | O22: =HYPERLINK(CONCATENATE("Project Name\01- Inspection Request - IR\STR\",B22,"-",C22,".PDF"),"IN") -> IN
A23: =ROW(A16) -> 16 | B23: WIR-MECH-016 | C23: 0 | E23: Zone: 03 Building:VS-10/VS11 | F23: drainage pipes in concrete | G23: 1 | H23: 5 | I23: 45990 | J23: 46005 | K23: B | L23: =IF(K23="UR","PENDING",IF(K23="CC","OPEN","CLOSED")) -> CLOSED | M23: =IF(J23="",TODAY()-I23,J23-I23) -> 15 | N23: =IF(P23="",0,(IF(J23="",TODAY()-P23,IF(J23-P23>0,J23-P23,0)))) -> 0 | O23: =HYPERLINK(CONCATENATE("Project Name\01- Inspection Request - IR\STR\",B23,"-",C23,".PDF"),"IN") -> IN
A24: =ROW(A17) -> 17 | B24: WIR-MECH-017 | C24: 0 | E24: Zone: 03 Building:VS-12-VS-13 | F24: drainage pipes in concrete | G24: 1 | H24: 5 | I24: 45990 | J24: 46005 | K24: B | L24: =IF(K24="UR","PENDING",IF(K24="CC","OPEN","CLOSED")) -> CLOSED | M24: =IF(J24="",TODAY()-I24,J24-I24) -> 15 | N24: =IF(P24="",0,(IF(J24="",TODAY()-P24,IF(J24-P24>0,J24-P24,0)))) -> 0 | O24: =HYPERLINK(CONCATENATE("Project Name\01- Inspection Request - IR\STR\",B24,"-",C24,".PDF"),"IN") -> IN
... A41: =ROW(A34) -> 34 | B41: WIR-MECH-034 | C41: 0 | E41: Zone: 04 Building:VS-01/VS-02 | F41: water supply network | G41: 1 | H41: 5 | I41: 46000 | J41: 46005 | K41: C | L41: =IF(K41="UR","PENDING",IF(K41="CC","OPEN","CLOSED")) -> CLOSED | M41: =IF(J41="",TODAY()-I41,J41-I41) -> 5 | N41: =IF(P41="",0,(IF(J41="",TODAY()-P41,IF(J41-P41>0,J41-P41,0)))) -> 0 | O41: =HYPERLINK(CONCATENATE("Project Name\01- Inspection Request - IR\STR\",B41,"-",C41,".PDF"),"IN") -> IN
A42: =ROW(A35) -> 35 | B42: WIR-MECH-034 | C42: 1 | E42: Zone: 04 Building:VS-01/VS-02 | F42: Installation of water supply network with all valves & WHA for Qaha VS-01/VS-02 | K42: UR | O42: =HYPERLINK(CONCATENATE("Project Name\01- Inspection Request - IR\STR\",B42,"-",C42,".PDF"),"IN") -> IN
A43: =ROW(A36) -> 36 | B43: WIR-MECH-035 | C43: 0 | E43: Zone: 04 Building:VS-03/VS-04 | F43: water supply network | G43: 1 | H43: 5 | I43: 46000 | J43: 46005 | K43: C | L43: =IF(K43="UR","PENDING",IF(K43="CC","OPEN","CLOSED")) -> CLOSED | M43: =IF(J43="",TODAY()-I43,J43-I43) -> 5 | N43: =IF(P43="",0,(IF(J43="",TODAY()-P43,IF(J43-P43>0,J43-P43,0)))) -> 0 | O43: =HYPERLINK(CONCATENATE("Project Name\01- Inspection Request - IR\STR\",B43,"-",C43,".PDF"),"IN") -> IN
A44: =ROW(A37) -> 37 | B44: WIR-MECH-035 | C44: 1 | E44: Zone: 04 Building:VS-03/VS-04 | F44: Installation of water supply network with all valves & WHA for Qaha VS-03/VS-04 | K44: UR
A45: =ROW(A38) -> 38 | B45: WIR-MECH-036 | C45: 0 | E45: Zone: 04 Building:VS-06/VS07 | F45: water supply network | G45: 1 | H45: 5 | I45: 46000 | J45: 46005 | K45: C | L45: =IF(K45="UR","PENDING",IF(K45="CC","OPEN","CLOSED")) -> CLOSED | M45: =IF(J45="",TODAY()-I45,J45-I45) -> 5 | N45: =IF(P45="",0,(IF(J45="",TODAY()-P45,IF(J45-P45>0,J45-P45,0)))) -> 0 | O45: =HYPERLINK(CONCATENATE("Project Name\01- Inspection Request - IR\STR\",B45,"-",C45,".PDF"),"IN") -> IN
A46: =ROW(A39) -> 39 | B46: WIR-MECH-036 | C46: 1 | E46: Zone: 04 Building:VS-06/VS07 | F46: Installation of water supply network with all valves & WHA for Qaha VS-06/VS-07 | K46: UR
A47: =ROW(A40) -> 40 | B47: WIR-MECH-037 | C47: 0 | E47: Zone: 04 Building:VS-08/VS-09 | F47: water supply network | G47: 1 | H47: 5 | I47: 46000 | J47: 46005 | K47: C | L47: =IF(K47="UR","PENDING",IF(K47="CC","OPEN","CLOSED")) -> CLOSED | M47: =IF(J47="",TODAY()-I47,J47-I47) -> 5 | N47: =IF(P47="",0,(IF(J47="",TODAY()-P47,IF(J47-P47>0,J47-P47,0)))) -> 0 | O47: =HYPERLINK(CONCATENATE("Project Name\01- Inspection Request - IR\STR\",B47,"-",C47,".PDF"),"IN") -> IN
A48: =ROW(A41) -> 41 | B48: WIR-MECH-037 | C48: 1 | E48: Zone: 04 Building:VS-08/VS-09 | F48: Installation of water supply network with all valves & WHA for Qaha VS-08/VS-09 | K48: UR
A49: =ROW(A42) -> 42 | B49: WIR-MECH-038 | C49: 0 | E49: Zone: 03 Building:VS-10/VS11 | F49: water supply network | G49: 1 | H49: 5 | I49: 46000 | J49: 46005 | K49: C | L49: =IF(K49="UR","PENDING",IF(K49="CC","OPEN","CLOSED")) -> CLOSED | M49: =IF(J49="",TODAY()-I49,J49-I49) -> 5 | N49: =IF(P49="",0,(IF(J49="",TODAY()-P49,IF(J49-P49>0,J49-P49,0)))) -> 0 | O49: =HYPERLINK(CONCATENATE("Project Name\01- Inspection Request - IR\STR\",B49,"-",C49,".PDF"),"IN") -> IN
A50: =ROW(A43) -> 43 | B50: WIR-MECH-038 | C50: 1 | E50: Zone: 03 Building:VS-10/VS11 | F50: Installation of water supply network with all valves & WHA for Qaha VS-10/VS11 | K50: UR
A51: =ROW(A44) -> 44 | B51: WIR-MECH-039 | C51: 0 | E51: Zone: 03 Building:VS-12-VS-13 | F51: water supply network | G51: 1 | H51: 5 | I51: 46000 | J51: 46005 | K51: C | L51: =IF(K51="UR","PENDING",IF(K51="CC","OPEN","CLOSED")) -> CLOSED | M51: =IF(J51="",TODAY()-I51,J51-I51) -> 5 | N51: =IF(P51="",0,(IF(J51="",TODAY()-P51,IF(J51-P51>0,J51-P51,0)))) -> 0 | O51: =HYPERLINK(CONCATENATE("Project Name\01- Inspection Request - IR\STR\",B51,"-",C51,".PDF"),"IN") -> IN
A52: =ROW(A45) -> 45 | B52: WIR-MECH-039 | C52: 1 | E52: Zone: 03 Building:VS-12-VS-13 | F52: Installation of water supply network with all valves & WHA for Qaha VS-12/VS13 | K52: UR
A53: =ROW(A46) -> 46 | B53: WIR-MECH-040 | C53: 0 | E53: Zone: 03 Building:VS-14/VS-15 | F53: water supply network | G53: 1 | H53: 5 | I53: 46000 | J53: 46005 | K53: C | L53: =IF(K53="UR","PENDING",IF(K53="CC","OPEN","CLOSED")) -> CLOSED | M53: =IF(J53="",TODAY()-I53,J53-I53) -> 5 | N53: =IF(P53="",0,(IF(J53="",TODAY()-P53,IF(J53-P53>0,J53-P53,0)))) -> 0 | O53: =HYPERLINK(CONCATENATE("Project Name\01- Inspection Request - IR\STR\",B53,"-",C53,".PDF"),"IN") -> IN
A54: =ROW(A47) -> 47 | B54: WIR-MECH-040 | C54: 1 | E54: Zone: 03 Building:VS-14/VS-15 | F54: Installation of water supply network with all valves & WHA for Qaha VS-14/VS-15 | K54: UR
A55: =ROW(A48) -> 48 | B55: WIR-MECH-041 | C55: 0 | E55: Zone: 03 Building:VS-16/VS-17 | F55: water supply network | G55: 1 | H55: 5 | I55: 46000 | J55: 46005 | K55: C | L55: =IF(K55="UR","PENDING",IF(K55="CC","OPEN","CLOSED")) -> CLOSED | M55: =IF(J55="",TODAY()-I55,J55-I55) -> 5 | N55: =IF(P55="",0,(IF(J55="",TODAY()-P55,IF(J55-P55>0,J55-P55,0)))) -> 0 | O55: =HYPERLINK(CONCATENATE("Project Name\01- Inspection Request - IR\STR\",B55,"-",C55,".PDF"),"IN") -> IN
A56: =ROW(A49) -> 49 | B56: WIR-MECH-041 | C56: 1 | E56: Zone: 03 Building:VS-16/VS-17 | F56: Installation of water supply network with all valves & WHA for Qaha VS-16/VS-17 | K56: UR
...

Sheet SURV
A1: Inspection Request - SURV | K1: A | L1: Approved | N1: Date: | O1: =TODAY() -> 46114
K2: B | L2: Approved with notes
K3: C | L3: Reject & Resubmit
K4: CC | L4: Not Resubmitted
K5: UR | L5: Under Review
A6: DOCUMENT REFERENCE NO | D6: Element | E6: Location | F6: DESCRIPTION | G6: Attachment | I6: Outgoing to Consultant | K6: Code Action | L6: Status | M6: Progress | N6: Over Duration | O6: scan | P6: Duration
A7: No. | B7: Reference | C7: REV | G7: Dwg | H7: Report | I7: Submission date | J7: Received Date
A9: 1 | B9: WIR-SURV-001 | C9: 0 | D9: Excavation | E9: Zone: 2 Building: GA-01 | F9: Excavation Level | I9: 45788 | J9: 45977 | K9: C | L9: CLOSED | M9: 11 | N9: 10 | O9: IN | P9: =IF(C9=0,I9+1,IF(C9>0,I9+1)) -> 45789
A10: 2 | B10: WIR-SURV-002 | C10: 0 | D10: General | E10: Zone: 2 Building: GA-01 | F10: Plain Concrete (PC) | I10: 45788 | J10: 45977 | K10: C | L10: CLOSED | M10: 11 | N10: 10 | O10: IN | P10: =IF(C10=0,I10+1,IF(C10>0,I10+1)) -> 45789
A11: 3 | B11: WIR-SURV-003 | C11: 0 | D11: General | E11: Zone: 2 Building: GA-01 | F11: Reinforced Concrete (RC) | I11: 45788 | J11: 45977 | K11: C | L11: CLOSED | M11: 11 | N11: 10 | O11: IN | P11: =IF(C11=0,I11+1,IF(C11>0,I11+1)) -> 45789
A12: 4 | B12: WIR-SURV-004 | C12: 0 | D12: General | E12: Zone: 2 Building: GA-01 | F12: Columns | I12: 45788 | J12: 45977 | K12: C | L12: CLOSED | M12: 11 | N12: 10 | O12: IN | P12: =IF(C12=0,I12+1,IF(C12>0,I12+1)) -> 45789
A13: 5 | B13: WIR-SURV-005 | C13: 0 | D13: General | E13: Zone: 2 Building: GA-02 | F13: Foundation Level | I13: 45788 | J13: 45977 | K13: C | L13: CLOSED | M13: 11 | N13: 10 | O13: IN | P13: =IF(C13=0,I13+1,IF(C13>0,I13+1)) -> 45789
A14: 6 | B14: WIR-SURV-006 | C14: 0 | D14: General | E14: Zone: 2 Building: GA-02 | F14: Plain Concrete (PC) | I14: 45788 | J14: 45977 | K14: C | L14: CLOSED | M14: 11 | N14: 10 | O14: IN | P14: =IF(C14=0,I14+1,IF(C14>0,I14+1)) -> 45789
A15: 7 | B15: WIR-SURV-007 | C15: 0 | D15: General | E15: Zone: 2 Building: GA-02 | F15: Reinforced Concrete (RC) | I15: 45788 | J15: 45977 | K15: C | L15: CLOSED | M15: 11 | N15: 10 | O15: IN | P15: =IF(C15=0,I15+1,IF(C15>0,I15+1)) -> 45789
A16: 8 | B16: WIR-SURV-008 | C16: 0 | D16: General | E16: Zone: 2 Building: GA-02 | F16: Columns | I16: 45788 | J16: 45977 | K16: C | L16: CLOSED | M16: 11 | N16: 10 | O16: IN | P16: =IF(C16=0,I16+1,IF(C16>0,I16+1)) -> 45789
A17: 9 | B17: WIR-SURV-009 | C17: 0 | D17: General | E17: Zone: 2 Building: GA-03 | F17: Foundation Level | I17: 45788 | J17: 46344 | K17: C | L17: CLOSED | M17: 13 | N17: 12 | O17: IN | P17: =IF(C17=0,I17+1,IF(C17>0,I17+1)) -> 45789
A18: 10 | B18: WIR-SURV-010 | C18: 0 | D18: General | E18: Zone: 2 Building: GA-03 | F18: Plain Concrete (PC) | I18: 45788 | J18: 46344 | K18: C | L18: CLOSED | M18: 13 | N18: 12 | O18: IN | P18: =IF(C18=0,I18+1,IF(C18>0,I18+1)) -> 45789
A19: 11 | B19: WIR-SURV-011 | C19: 0 | D19: General | E19: Zone: 2 Building: GA-03 | F19: Reinforced Concrete (RC) | I19: 45788 | J19: 46344 | K19: C | L19: CLOSED | M19: 13 | N19: 12 | O19: IN | P19: =IF(C19=0,I19+1,IF(C19>0,I19+1)) -> 45789
A20: 12 | B20: WIR-SURV-012 | C20: 0 | D20: General | E20: Zone: 2 Building: GA-03 | F20: Columns | I20: 45788 | J20: 46344 | K20: C | L20: CLOSED | M20: 13 | N20: 12 | O20: IN | P20: =IF(C20=0,I20+1,IF(C20>0,I20+1)) -> 45789
... A53: 45 | B53: WIR-SURV-045 | C53: 0 | D53: Excavation | E53: Zone: 2 Building: Gathering | F53: Excavation Level | I53: 45788 | J53: 46344 | K53: C | L53: CLOSED | M53: 13 | N53: 12 | O53: IN | P53: =IF(C53=0,I53+1,IF(C53>0,I53+1)) -> 45789
A54: 46 | B54: WIR-SURV-046 | C54: 0 | D54: General | E54: Zone: 2 Building: Gathering | F54: Plain Concrete (PC) | I54: 45788 | J54: 46344 | K54: C | L54: CLOSED | M54: 13 | N54: 0 | O54: IN
A55: 47 | B55: WIR-SURV-047 | C55: 0 | D55: General | E55: Zone: 2 Building: Gathering | F55: Reinforced Concrete (RC) | I55: 45788 | J55: 46344 | K55: C | L55: CLOSED | M55: 13 | N55: 0 | O55: IN
A56: 48 | B56: WIR-SURV-048 | C56: 0 | D56: General | E56: Zone: 2 Building: Gathering | F56: Columns | I56: 45788 | J56: 46344 | K56: C | L56: CLOSED | M56: 13 | N56: 0 | O56: IN
A57: 49 | B57: WIR-SURV-049 | C57: 0 | D57: General | E57: Zone: 2 Building: Control Room | F57: Excavation Level | I57: 45788 | J57: 46344 | K57: C | L57: CLOSED | M57: 13 | N57: 0 | O57: IN
A58: 50 | B58: WIR-SURV-050 | C58: 0 | D58: General | E58: Zone: 2 Building: Control Room | F58: Plain Concrete (PC) | I58: 45788 | J58: 46344 | K58: C | L58: CLOSED | M58: 13 | N58: 0 | O58: IN
A59: 51 | B59: WIR-SURV-051 | C59: 0 | D59: General | E59: Zone: 2 Building: Control Room | F59: Reinforced Concrete (RC) | I59: 45788 | J59: 46344 | K59: C | L59: CLOSED | M59: 13 | N59: 0 | O59: IN
A60: 52 | B60: WIR-SURV-052 | C60: 0 | D60: General | E60: Zone: 2 Building: Control Room | F60: Columns | I60: 45788 | J60: 46344 | K60: C | L60: CLOSED | M60: 13 | N60: 0 | O60: IN
A61: 53 | B61: WIR-SURV-053 | C61: 0 | D61: General | E61: Zone: 2 Building: Maintance Store | F61: Excavation Level | I61: 45788 | J61: 46344 | K61: C | L61: CLOSED | M61: 13 | N61: 0 | O61: IN
A62: 54 | B62: WIR-SURV-054 | C62: 0 | D62: General | E62: Zone: 2 Building: Maintance Store | F62: Plain Concrete (PC) | I62: 45788 | J62: 46344 | K62: C | L62: CLOSED | M62: 13 | N62: 0 | O62: IN
A63: 55 | B63: WIR-SURV-055 | C63: 0 | D63: General | E63: Zone: 2 Building: Maintance Store | F63: Reinforced Concrete (RC) | I63: 45788 | J63: 46344 | K63: C | L63: CLOSED | M63: 13 | N63: 0 | O63: IN
A64: 56 | B64: WIR-SURV-056 | C64: 0 | D64: General | E64: Zone: 2 Building: Maintance Store | F64: Columns | I64: 45788 | J64: 46344 | K64: C | L64: CLOSED | M64: 13 | N64: 0 | O64: IN
A65: 57 | B65: WIR-SURV-057 | C65: 0 | D65: General | E65: Zone: 2 Building: Frist Aid | F65: Excavation Level | I65: 45788 | J65: 46344 | K65: C | L65: CLOSED | M65: 13 | N65: 0 | O65: IN
... A88: 80 | B88: WIR-SURV-020 | C88: 1 | D88: General | E88: Zone: 2 Building: GA-05 | F88: Columns | I88: 46002 | J88: 46339 | K88: B | L88: CLOSED | M88: 1 | N88: 0 | O88: IN
A89: 81 | B89: WIR-SURV-021 | C89: 1 | D89: General | E89: Zone: 2 Building: GA-06 | F89: Foundation Level | I89: 46002 | J89: 46339 | K89: B | L89: CLOSED | M89: 1 | N89: 0 | O89: IN | P89: =IF(C89=0,I89+1,IF(C89>0,I89+1)) -> 46003
A90: 82 | B90: WIR-SURV-022 | C90: 1 | D90: General | E90: Zone: 2 Building: GA-06 | F90: Plain Concrete (PC) | I90: 46002 | J90: 46339 | K90: B | L90: CLOSED | M90: 1 | N90: 0 | O90: IN | P90: =IF(C90=0,I90+1,IF(C90>0,I90+1)) -> 46003
A91: 83 | B91: WIR-SURV-023 | C91: 1 | D91: General | E91: Zone: 2 Building: GA-06 | F91: Reinforced Concrete (RC) | I91: 46002 | J91: 46339 | K91: B | L91: CLOSED | M91: 1 | N91: 0 | O91: IN | P91: =IF(C91=0,I91+1,IF(C91>0,I91+1)) -> 46003
A92: 84 | B92: WIR-SURV-024 | C92: 1 | D92: General | E92: Zone: 2 Building: GA-06 | F92: Columns | I92: 46002 | J92: 46339 | K92: B | L92: CLOSED | M92: 1 | N92: 0 | O92: IN | P92: =IF(C92=0,I92+1,IF(C92>0,I92+1)) -> 46003
A93: 85 | B93: WIR-SURV-025 | C93: 1 | D93: General | E93: Zone: 2 Building: GA-07 | F93: Foundation Level | I93: 46002 | J93: 46339 | K93: B | L93: CLOSED | M93: 1 | N93: 0 | O93: IN | P93: =IF(C93=0,I93+1,IF(C93>0,I93+1)) -> 46003
A94: 86 | B94: WIR-SURV-026 | C94: 1 | D94: General | E94: Zone: 2 Building: GA-07 | F94: Plain Concrete (PC) | I94: 46002 | J94: 46339 | K94: B | L94: CLOSED | M94: 1 | N94: 0 | O94: IN | P94: =IF(C94=0,I94+1,IF(C94>0,I94+1)) -> 46003
A95: 87 | B95: WIR-SURV-027 | C95: 1 | D95: General | E95: Zone: 2 Building: GA-07 | F95: Reinforced Concrete (RC) | I95: 46002 | J95: 46339 | K95: B | L95: CLOSED | M95: 1 | N95: 0 | O95: IN | P95: =IF(C95=0,I95+1,IF(C95>0,I95+1)) -> 46003
...

Sheet SUMMARY REPORTS
D1: D
AB2: WORK ACTIVITIES | AC2: Code Action | AE2: Issue for | AF2: FLOOR | AG2: ELEMENT
E3: 1686 | G3: INSPECTION REQUEST FOR All PROJECT | AB3: Column1 | AC3: Column2 | AD3: Column3 | AE3: Column4 | AF3: Column5 | AG3: Column6 | AH3: Column7 | AI3: Column8 | AJ3: Column9 | AK3: Column10
G4: A | H4: B | I4: C | J4: UR | K4: D | AB4: STR | AC4: A | AD4: APPROVED | AE4: APPROVAL | AG4: str | AH4: serv | AI4: arch | AJ4: elec | AK4: mech
D5: =SUM(D13,D21,D30,D39,D49) -> 2123 | E5: =SUM(E13,E21,E30,E39,E49) -> 1686 | G5: =SUM(D8+D16+D25+D34+D44) -> 0 | H5: =SUM(E9,E17,E26,E35,E45) -> 1203 | I5: =SUM(E10,E18,E27,E36,E46) -> 115 | J5: =SUM(E11,E19,E28,E37,E47) -> 345 | K5: =SUM(E10) -> 0 | L5: =SUM(G5:K5) -> 1663 | AB5: ARCH | AC5: B | AD5: APPROVE AS NOTET | AE5: INFORMATION | AF5: PC | AG5: Concrete | AH5: Concrete | AI5: Block | AJ5: Lighting
G6: =G5/$E$3 -> 0 | H6: =H5/$E$3 -> 0.71352313 | I6: =I5/$E$3 -> 0.068208778 | J6: =J5/$E$3 -> 0.20462633 | K6: =K5/$E$3 -> 0 | AB6: ELEC | AC6: C | AD6: REVICE & RESUBMIT | AF6: RC | AG6: Con.slabs | AH6: Con.slabs | AI6: Cladding | AJ6: Power
B7: Description | C7: Code | D7: Quantity | S7: 661 | T7: 175 | U7: 203 | V7: 771 | W7: 341 | X7: =SUM(S7:W7) -> 2151 | AB7: MECH | AC7: D | AD7: REJECTED | AF7: B.COL | AG7: Insulation | AH7: Block | AI7: Plastering | AJ7: Low Current
B8: IR SU | C8: A | D8: =COUNTIF(SURV!K8:K1992,"A") -> 0 | AB8: SERV | AC8: UR | AD8: UNDER REVIEW | AF8: G.COL | AG8: Back Filling | AH8: Cladding | AI8: Insulation
C9: B | D9: 279 | E9: 279 | F9: Profast-PROJECT NAME INSPECTION REQUEST | AB9: SEFT | AC9: CA | AD9: CANCEL | AF9: 1.COL | AG9: Excavation | AH9: Plastering | AI9: Painting
C10: CC | D10: 59 | E10: 0 | AB10: MATERAIL | AC10: CC | AD10: Not Resubmitted | AF10: 2.COL | AG10: Finishing | AH10: Insulation | AI10: Marble
C11: UR | D11: 3 | E11: 0 | AB11: G | AC11: C , B | AF11: 3.COL | AH11: Back Filling | AI11: Stone
C12: D | D12: 0 | E12: 0 | AF12: 4.COL | AH12: Painting | AI12: G.poard
D13: =SUM(D8,D8:D12) -> 341 | E13: =SUM(E9:E12) -> 279 | AF13: R.COL | AH13: Excavation | AI13: celar
AE14: B.FLOOR | AF14: B.SLAB | AH14: General
B15: Description | C15: Code | D15: Quantity | AE15: G.FLOOR | AF15: G.SLAB | AI15: Handrail
B16: IR STR | C16: A | D16: =COUNTIF(STR!K9:K2055,"A") -> 0 | AE16: 1.FLOOR | AF16: 1.SLAB | AI16: GRC
C17: B | D17: 289 | E17: 364 | AE17: 2.FLOOR | AF17: 2.SLAB
C18: CC | D18: 192 | E18: 70 | AE18: 3.FLOOR | AF18: 3.SLAB
C19: UR | D19: 152 | E19: 71 | AE19: 4.FLOOR | AF19: 4.SLAB
C20: D | D20: 16 | E20: 18 | AE20: R.FLOOR | AF20: R.SLAB
D21: =SUM(D16:D20) -> 649 | E21: =SUM(E17:E20) -> 523 | AE21: Landscap | AF21: Re.Wall
AE22: Roods | AF22: Stairs
AF23: S.O.G
B24: Description | C24: Code | D24: Quantity | AF24: GENERAL
B25: IR ELEC | C25: A | D25: =COUNTIF(ELEC!K9:K2003,"A") -> 0 | AF25: ELEV
C26: B | D26: 38 | E26: 70 | AF26: Ramp
C27: CC | D27: 23 | E27: 21 | AF27: Core
C28: UR | D28: 141 | E28: 2 | AF28: Tank
C29: D | D29: =COUNTIF(ELEC!K9:K2007,"D") -> 1 | E29: 1 | AF29: Post
D30: =SUM(D25:D29) -> 203 | E30: =SUM(E26:E29) -> 94 | AF30: Entrance
B33: Description | C33: Code | D33: Quantity
B34: IR MECH | C34: A | D34: =COUNTIF(MECH!$K$8:K1956,"A") -> 0
C35: B | D35: 277 | E35: 480
C36: CC | D36: 19 | E36: 2
C37: UR | D37: 457 | E37: 250
C38: D | D38: =COUNTIF(MECH!$K$8:K1960,"D") -> 0 | E38: 0
D39: =SUM(D34:D38) -> 753 | E39: =SUM(E35:E38) -> 732
B43: Description | C43: Code | D43: Quantity
B44: IR ARCH | C44: A | D44: =COUNTIF(ARCH!$K$13:K1998,"A") -> 0
C45: B | D45: 12 | E45: 10
...

Sheet Rola
A1: Inspection Request - SURV
A6: DOCUMENT REFERENCE NO | D6: Element | E6: Location | F6: DESCRIPTION | G6: Attachment | I6: Outgoing to Consultant
A7: No. | B7: Reference | C7: REV | G7: Dwg | H7: Report | I7: Submission date | J7: Received Date
A8: =ROW(A1) -> 1 | B8: WIR-CIVIL-23 | D8: STR | I8: 45990
A9: =ROW(A2) -> 2 | B9: WIR-CIVIL-24 | D9: STR | I9: 45990
A10: =ROW(A3) -> 3 | B10: WIR-CIVIL-25 | D10: STR | I10: 45990
A11: =ROW(A4) -> 4 | B11: WIR-CIVIL-26 | D11: STR | I11: 45990
A12: =ROW(A5) -> 5 | B12: WIR-CIVIL-27 | D12: STR | I12: 45990
A13: =ROW(A6) -> 6 | B13: WIR-CIVIL-28 | D13: STR | I13: 45990
A14: =ROW(A7) -> 7 | B14: WIR-CIVIL-29 | D14: STR | I14: 45990
A15: =ROW(#REF!) -> #REF! | B15: WIR-CIVIL-30 | D15: STR | I15: 45990
A16: =ROW(A8) -> 8 | B16: WIR-CIVIL-31 | D16: STR | I16: 45990
A17: =ROW(A9) -> 9 | B17: WIR-CIVIL-32 | D17: STR | I17: 45990
A18: =ROW(A10) -> 10 | B18: WIR-CIVIL-33 | D18: STR | I18: 45990
A19: =ROW(A11) -> 11 | B19: WIR-CIVIL-34 | D19: STR | I19: 45990
A20: =ROW(A12) -> 12 | B20: WIR-CIVIL-35 | D20: STR | I20: 45990
A21: =ROW(A13) -> 13 | B21: WIR-CIVIL-36 | D21: STR | I21: 45990
A22: =ROW(A14) -> 14 | B22: WIR-CIVIL-37 | D22: STR | I22: 45990
A23: =ROW(A15) -> 15 | B23: WIR-CIVIL-38 | D23: STR | I23: 45990
A24: =ROW(A16) -> 16 | B24: WIR-CIVIL-39 | D24: STR | I24: 45990
A25: =ROW(A17) -> 17 | B25: WIR-CIVIL-40 | D25: STR | I25: 45990
A26: =ROW(A18) -> 18 | B26: WIR-CIVIL-41 | D26: STR | I26: 45990
A27: =ROW(A19) -> 19 | B27: WIR-CIVIL-42 | D27: STR | I27: 45990
... A91: =ROW(A83) -> 83 | B91: WIR-CIVIL-106 | D91: STR | I91: 45990
A92: 266 | B92: WIR-Civil-201 | C92: 0 | D92: STR | E92: ZONE :3-4 Building : Q-C(03-04) | F92: Prevention Termites . Polythene Sheet | I92: 46048
A93: 267 | B93: WIR-Civil-202 | C93: 0 | D93: STR | E93: ZONE :3-4 Building : Q-C(03-04) | F93: Form Work of P.C Footing | I93: 46048
A94: 268 | B94: WIR-Civil-203 | C94: 0 | D94: STR | E94: ZONE :3-4 Building : Q-C(03-04) | F94: Pouring For P.C Footing | I94: 46048
A95: 269 | B95: WIR-Civil-204 | C95: 0 | D95: STR | E95: ZONE :3-4 Building : Q-C(03-04) | F95: Form and Steel Work of R.C raft | I95: 46048
A96: 270 | B96: WIR-Civil-205 | C96: 0 | D96: STR | E96: ZONE :3-4 Building : Q-C(03-04) | F96: Pouring For R.C raft | I96: 46048
A97: 271 | B97: WIR-Civil-206 | C97: 0 | D97: STR | E97: ZONE :3-4 Building : Q-C(03-04) | F97: Surface Preparation for R.C Footing Before Insulation | I97: 46048
A98: 272 | B98: WIR-Civil-207 | C98: 0 | D98: STR | E98: ZONE :3-4 Building : Q-C(03-04) | F98: Insulation of R.C raft | I98: 46048
A99: 273 | B99: WIR-Civil-208 | C99: 0 | D99: STR | E99: ZONE :3-4 Building : Q-C(03-04) | F99: Steel structure working | I99: 46048
A100: 274 | B100: WIR-Civil-209 | C100: 0 | D100: STR | E100: ZONE :3-4 Building : Q-C(03-04) | F100: Pouring For Screed ( ground floor ) | I100: 46048
A101: 275 | B101: WIR-Civil-210 | C101: 0 | D101: STR | E101: ZONE :3-4 Building : Q-C(03-04) | F101: Installation of H.C.S | I101: 46048
A102: 276 | B102: WIR-Civil-211 | C102: 0 | D102: STR | E102: ZONE :3-4 Building : Q-C(03-04) | F102: Steel works of Screed after H.C.S | I102: 46048
A103: 277 | B103: WIR-Civil-212 | C103: 0 | D103: STR | E103: ZONE :3-4 Building : Q-C(03-04) | F103: Pouring For Screed | I103: 46048
... A144: 386 | B144: WIR-Civil-322 | C144: 0 | D144: STR | E144: ZONE : 3-4 Building : Q-C(11-12-15-16) | F144: Pouring For Screed | I144: 46048
A160: =ROW(A152) -> 152 | B160: WIR-MECH-015 | D160: MECH | I160: 45990
A161: =ROW(A153) -> 153 | B161: WIR-MECH-016 | D161: MECH | I161: 45990
A162: =ROW(A154) -> 154 | B162: WIR-MECH-017 | D162: MECH | I162: 45990
...
